Traceback (most recent call last):
  File "/home/zhang146/anaconda3/envs/continualrl/lib/python3.10/multiprocessing/forkserver.py", line 274, in main
  File "/home/zhang146/anaconda3/envs/continualrl/lib/python3.10/multiprocessing/forkserver.py", line 313, in _serve_one
  File "/home/zhang146/anaconda3/envs/continualrl/lib/python3.10/multiprocessing/spawn.py", line 125, in _main
  File "/home/zhang146/anaconda3/envs/continualrl/lib/python3.10/multiprocessing/spawn.py", line 236, in prepare
  File "/home/zhang146/anaconda3/envs/continualrl/lib/python3.10/multiprocessing/spawn.py", line 287, in _fixup_main_from_path
Traceback (most recent call last):
  File "/home/zhang146/anaconda3/envs/continualrl/lib/python3.10/runpy.py", line 289, in run_path
  File "/home/zhang146/anaconda3/envs/continualrl/lib/python3.10/multiprocessing/forkserver.py", line 274, in main
  File "/home/zhang146/anaconda3/envs/continualrl/lib/python3.10/runpy.py", line 96, in _run_module_code
  File "/home/zhang146/anaconda3/envs/continualrl/lib/python3.10/multiprocessing/forkserver.py", line 313, in _serve_one
  File "/home/zhang146/anaconda3/envs/continualrl/lib/python3.10/runpy.py", line 86, in _run_code
  File "/home/zhang146/anaconda3/envs/continualrl/lib/python3.10/multiprocessing/spawn.py", line 125, in _main
  File "/home/zhang146/stable-baselines3/main_lowvar.py", line 4, in <module>
  File "/home/zhang146/anaconda3/envs/continualrl/lib/python3.10/multiprocessing/spawn.py", line 236, in prepare
  File "/home/zhang146/anaconda3/envs/continualrl/lib/python3.10/site-packages/sklearn/neighbors/__init__.py", line 17, in <module>
  File "/home/zhang146/anaconda3/envs/continualrl/lib/python3.10/multiprocessing/spawn.py", line 287, in _fixup_main_from_path
  File "/home/zhang146/anaconda3/envs/continualrl/lib/python3.10/site-packages/sklearn/neighbors/_nca.py", line 19, in <module>
  File "/home/zhang146/anaconda3/envs/continualrl/lib/python3.10/runpy.py", line 289, in run_path
  File "/home/zhang146/anaconda3/envs/continualrl/lib/python3.10/site-packages/sklearn/decomposition/__init__.py", line 16, in <module>
  File "/home/zhang146/anaconda3/envs/continualrl/lib/python3.10/runpy.py", line 96, in _run_module_code
  File "/home/zhang146/anaconda3/envs/continualrl/lib/python3.10/site-packages/sklearn/decomposition/_sparse_pca.py", line 13, in <module>
  File "/home/zhang146/anaconda3/envs/continualrl/lib/python3.10/runpy.py", line 86, in _run_code
  File "/home/zhang146/anaconda3/envs/continualrl/lib/python3.10/site-packages/sklearn/linear_model/__init__.py", line 34, in <module>
  File "/home/zhang146/stable-baselines3/main_lowvar.py", line 4, in <module>
  File "sklearn/linear_model/_sgd_fast.pyx", line 1, in init sklearn.linear_model._sgd_fast
  File "/home/zhang146/anaconda3/envs/continualrl/lib/python3.10/site-packages/sklearn/neighbors/__init__.py", line 17, in <module>
  File "/home/zhang146/anaconda3/envs/continualrl/lib/python3.10/site-packages/sklearn/neighbors/_nca.py", line 19, in <module>
ImportError: /home/zhang146/anaconda3/envs/continualrl/lib/python3.10/site-packages/sklearn/utils/_weight_vector.cpython-310-x86_64-linux-gnu.so: cannot open shared object file: Too many open files in system
  File "/home/zhang146/anaconda3/envs/continualrl/lib/python3.10/site-packages/sklearn/decomposition/__init__.py", line 16, in <module>
  File "/home/zhang146/anaconda3/envs/continualrl/lib/python3.10/site-packages/sklearn/decomposition/_sparse_pca.py", line 13, in <module>
  File "/home/zhang146/anaconda3/envs/continualrl/lib/python3.10/site-packages/sklearn/linear_model/__init__.py", line 36, in <module>
  File "<frozen importlib._bootstrap>", line 1027, in _find_and_load
Traceback (most recent call last):
  File "/home/zhang146/anaconda3/envs/continualrl/lib/python3.10/multiprocessing/forkserver.py", line 274, in main
  File "/home/zhang146/anaconda3/envs/continualrl/lib/python3.10/multiprocessing/forkserver.py", line 313, in _serve_one
  File "/home/zhang146/anaconda3/envs/continualrl/lib/python3.10/multiprocessing/spawn.py", line 125, in _main
  File "/home/zhang146/anaconda3/envs/continualrl/lib/python3.10/multiprocessing/spawn.py", line 236, in prepare
  File "/home/zhang146/anaconda3/envs/continualrl/lib/python3.10/multiprocessing/spawn.py", line 287, in _fixup_main_from_path
  File "/home/zhang146/anaconda3/envs/continualrl/lib/python3.10/runpy.py", line 289, in run_path
  File "/home/zhang146/anaconda3/envs/continualrl/lib/python3.10/runpy.py", line 96, in _run_module_code
  File "/home/zhang146/anaconda3/envs/continualrl/lib/python3.10/runpy.py", line 86, in _run_code
  File "/home/zhang146/stable-baselines3/main_lowvar.py", line 4, in <module>
  File "/home/zhang146/anaconda3/envs/continualrl/lib/python3.10/site-packages/sklearn/neighbors/__init__.py", line 17, in <module>
  File "/home/zhang146/anaconda3/envs/continualrl/lib/python3.10/site-packages/sklearn/neighbors/_nca.py", line 19, in <module>
  File "/home/zhang146/anaconda3/envs/continualrl/lib/python3.10/site-packages/sklearn/decomposition/__init__.py", line 29, in <module>
  File "/home/zhang146/anaconda3/envs/continualrl/lib/python3.10/site-packages/sklearn/decomposition/_lda.py", line 27, in <module>
ImportError: /home/zhang146/anaconda3/envs/continualrl/lib/python3.10/site-packages/sklearn/decomposition/_online_lda_fast.cpython-310-x86_64-linux-gnu.so: cannot open shared object file: Too many open files in system
  File "<frozen importlib._bootstrap>", line 1006, in _find_and_load_unlocked
  File "<frozen importlib._bootstrap>", line 688, in _load_unlocked
  File "<frozen importlib._bootstrap_external>", line 879, in exec_module
Traceback (most recent call last):
  File "/home/zhang146/anaconda3/envs/continualrl/lib/python3.10/multiprocessing/forkserver.py", line 274, in main
  File "/home/zhang146/anaconda3/envs/continualrl/lib/python3.10/multiprocessing/forkserver.py", line 313, in _serve_one
  File "/home/zhang146/anaconda3/envs/continualrl/lib/python3.10/multiprocessing/spawn.py", line 125, in _main
  File "/home/zhang146/anaconda3/envs/continualrl/lib/python3.10/multiprocessing/spawn.py", line 236, in prepare
  File "/home/zhang146/anaconda3/envs/continualrl/lib/python3.10/multiprocessing/spawn.py", line 287, in _fixup_main_from_path
  File "/home/zhang146/anaconda3/envs/continualrl/lib/python3.10/runpy.py", line 289, in run_path
  File "/home/zhang146/anaconda3/envs/continualrl/lib/python3.10/runpy.py", line 96, in _run_module_code
  File "/home/zhang146/anaconda3/envs/continualrl/lib/python3.10/runpy.py", line 86, in _run_code
  File "/home/zhang146/stable-baselines3/main_lowvar.py", line 19, in <module>
  File "/home/zhang146/anaconda3/envs/continualrl/lib/python3.10/site-packages/d3rlpy/__init__.py", line 8, in <module>
  File "/home/zhang146/anaconda3/envs/continualrl/lib/python3.10/site-packages/d3rlpy/algos/__init__.py", line 1, in <module>
  File "<frozen importlib._bootstrap>", line 1027, in _find_and_load
  File "<frozen importlib._bootstrap>", line 1002, in _find_and_load_unlocked
  File "<frozen importlib._bootstrap>", line 945, in _find_spec
  File "<frozen importlib._bootstrap_external>", line 1439, in find_spec
  File "<frozen importlib._bootstrap_external>", line 1411, in _get_spec
  File "<frozen importlib._bootstrap_external>", line 1548, in find_spec
  File "<frozen importlib._bootstrap_external>", line 1591, in _fill_cache
OSError: [Errno 23] Too many open files in system: '/home/zhang146/anaconda3/envs/continualrl/lib/python3.10/site-packages/d3rlpy/algos'
  File "<frozen importlib._bootstrap_external>", line 1016, in get_code
  File "<frozen importlib._bootstrap_external>", line 1073, in get_data
OSError: [Errno 23] Too many open files in system: '/home/zhang146/anaconda3/envs/continualrl/lib/python3.10/site-packages/sklearn/linear_model/_ridge.py'
Traceback (most recent call last):
  File "/home/zhang146/stable-baselines3/main_lowvar.py", line 943, in <module>
    dummy_env = SubprocVecEnv(dummy_env_fns)
  File "/home/zhang146/stable-baselines3/stable_baselines3/common/vec_env/subproc_vec_env.py", line 119, in __init__
    observation_space, action_space = self.remotes[0].recv()
  File "/home/zhang146/anaconda3/envs/continualrl/lib/python3.10/multiprocessing/connection.py", line 250, in recv
    buf = self._recv_bytes()
  File "/home/zhang146/anaconda3/envs/continualrl/lib/python3.10/multiprocessing/connection.py", line 414, in _recv_bytes
    buf = self._recv(4)
  File "/home/zhang146/anaconda3/envs/continualrl/lib/python3.10/multiprocessing/connection.py", line 379, in _recv
    chunk = read(handle, remaining)
ConnectionResetError: [Errno 104] Connection reset by peer
